Workbook

Sheet Инструкция
A1: Тестовые кейсы: калькулятор, JS-версия — без арифметических операций
A2: Книга для прогонов. Набор ручных тестовых кейсов для калькулятора в виде «Стандартный» (React + Vite): все разделы, кроме «Арифметических операций». Кейсы составлены по разделу «Требования к калькулятору» в README; полный набор — в test-cases.md. Тот же набор в Markdown — docs/test-cases-no-arithmetic.md.
A4: Как провести прогон
A5: 1. Параметры | B5: На листе «Сводка» заполните жёлтые ячейки: версию сборки из подвала страницы, стенд, браузер и ОС, своё имя, даты прогона.
A6: 2. Выполнение | B6: На листе «Прогон» выполняйте кейсы по порядку или отфильтруйте их по разделу и приоритету (стрелки в заголовках). Перед каждым кейсом верните калькулятор в исходное состояние (ОП-1).
A7: 3. Результаты | B7: Заполняйте только жёлтые столбцы J–M: «Статус» (выбор из списка), «Фактический результат», «Баг-репорт», «Комментарий». Столбцы A–I — описание кейса, их не меняйте.
A8: 4. Итоги | B8: Лист «Сводка» считает итоги сам: по статусам, разделам и приоритетам.
A10: Статусы
A11: Статус | B11: Когда ставить
A12: Не выполнялся | B12: Кейс ещё не проверяли. Стоит по умолчанию.
A13: Пройден | B13: На всех шагах фактический результат совпал с ожидаемым.
A14: Не пройден | B14: Хотя бы на одном шаге результат отличается. В «Фактический результат» запишите номер шага и что увидели, в «Баг-репорт» — номер или ссылку на заведённый дефект.
A15: Заблокирован | B15: Кейс нельзя выполнить: не получается выполнить предусловие или мешает другой дефект. Причину запишите в «Комментарий».
A16: Пропущен | B16: Кейс сознательно не выполняли в этом прогоне, например он не входит в объём смоук-теста. Причину запишите в «Комментарий».
A18: Приоритеты
A19: Высокий | B19: Основная функция: без неё калькулятором нельзя пользоваться.
A20: Средний | B20: Важная, но не основная функция.
A21: Низкий | B21: Граничные и редкие случаи.
A23: Общие предусловия
A24: ОП-1. Исходное состояние | B24: Страница калькулятора только что открыта или перезагружена (F5): на экране 0, строка выражения пуста, индикатора M нет, журнал пуст. Память и журнал живут только до перезагрузки страницы, поэтому перезагрузка — самый надёжный способ вернуться в исходное состояние между кейсами.
A25: ОП-2. Окружение | B25: Актуальная версия Chrome, Firefox или Safari; ширина окна не меньше 760 px, так что журнал виден справа от калькулятора (кроме кейсов, где ширина указана явно).
A26: ОП-3. Стенд | B26: https://calc.simdyanov.ru или локальный запуск (npm run dev → http://localhost:5173, Docker → http://localhost:8080). Версия сборки указана в подвале страницы — её нужно записывать в результаты прогона и баг-репорты.
A28: Обозначения
A29: Экран | B29: Основной экран с числом (data-testid="display").
A30: Выражение | B30: Строка над основным экраном (data-testid="expression").
A31: Журнал | B31: Панель «Журнал» (data-testid="history"), записи в ней — history-item.
A32: — | B32: Кнопки записаны так, как подписаны на калькуляторе: +, −, ×, ÷, =, %, ¹⁄ₓ, x², ²√x, +/−, ,, CE, C, ⌫, MC, MR, M+, M−, MS.
A33: — | B33: «Набрать 2,5» — нажать по очереди 2, ,, 5. Кнопки нажимаются мышью, если в кейсе не сказано иное.
A34: — | B34: Значения на экране записаны точно так, как они выводятся: пробел разделяет разряды, запятая — дробную часть (1 234 567,5).
A35: — | B35: Запись журнала обозначена как выражение → результат, например 12 + 30 = → 42.
A36: Шаги и результаты | B36: Номер строки в «Ожидаемом результате» совпадает с номером шага в «Шагах».
A38: Пример: кейс пройден (условные данные)
A39: ID | B39: TC-UI-01
A40: Статус | B40: Пройден
A41: Фактический результат | B41: Оставьте пустым: он совпал с ожидаемым.
A43: Пример: кейс не пройден (условные данные, не результат реального прогона)
A44: ID | B44: TC-INP-02
A45: Статус | B45: Не пройден
A46: Фактический результат | B46: Шаг 2: на экране 05, ожидалось 5
A47: Баг-репорт | B47: BUG-17
...

Sheet Прогон
A1: ID | B1: Название | C1: Раздел | D1: Приоритет | E1: Требование | F1: Предусловия | G1: Шаги | H1: Ожидаемый результат | I1: Постусловия | J1: Статус | K1: Фактический результат | L1: Баг-репорт | M1: Комментарий
A2: TC-UI-01 | B2: Исходное состояние после загрузки | C2: Интерфейс | D2: Высокий | E2: «Операции», «Журнал» | F2: ОП-2, ОП-3. Страница калькулятора ещё не открыта. | G2: 1. Открыть страницу калькулятора 2. Посмотреть на кнопки памяти 3. Посмотреть на журнал 4. Посмотреть на подвал страницы | H2: 1. Заголовок «Стандартный». Экран: 0; выражение пустое; индикатора M нет 2. MC и MR недоступны; M+, M−, MS доступны 3. Журнал виден справа, в нём текст «Журнал пока пуст»; кнопка с корзиной недоступна 4. Текст «Учебный проект · версия 1.0.0» | I2: Калькулятор в исходном состоянии (ОП-1); память и журнал пусты. | J2: Не выполнялся
A3: TC-INP-01 | B3: Ввод целого числа | C3: Ввод чисел | D3: Высокий | E3: «Ввод» | F3: ОП-1. | G3: 1. Нажать 1 2. Нажать 2, 3 | H3: 1. Экран: 1 2. Экран: 123; выражение пустое | I3: Набирается число 123, операций нет; журнал пуст. | J3: Не выполнялся
A4: TC-INP-02 | B4: Ведущие нули не допускаются | C4: Ввод чисел | D4: Средний | E4: «Ввод» | F4: ОП-1. | G4: 1. Нажать 0 три раза 2. Нажать 5 | H4: 1. Экран: 0 (не 000) 2. Экран: 5 (не 05) | I4: Набирается число 5. | J4: Не выполнялся
A5: TC-INP-03 | B5: Ввод дробного числа | C5: Ввод чисел | D5: Высокий | E5: «Ввод» | F5: ОП-1. | G5: 1. Нажать 3 2. Нажать , 3. Нажать 1, 4 | H5: 1. Экран: 3 2. Экран: 3, 3. Экран: 3,14 | I5: Набирается число 3,14. | J5: Не выполнялся
A6: TC-INP-04 | B6: Разделитель в начале числа | C6: Ввод чисел | D6: Средний | E6: «Ввод» | F6: ОП-1. | G6: 1. Нажать , 2. Нажать 5 | H6: 1. Экран: 0, 2. Экран: 0,5 | I6: Набирается число 0,5. | J6: Не выполнялся
A7: TC-INP-05 | B7: Второй разделитель игнорируется | C7: Ввод чисел | D7: Средний | E7: «Ввод» | F7: ОП-1. | G7: 1. Набрать 1,2 2. Нажать , 3. Нажать 3 | H7: 1. Экран: 1,2 2. Экран не изменился: 1,2 3. Экран: 1,23 | I7: Набирается число 1,23, в нём один разделитель. | J7: Не выполнялся
A8: TC-INP-06 | B8: Не более 15 цифр в целом числе | C8: Ввод чисел | D8: Средний | E8: «Ввод» | F8: ОП-1. | G8: 1. Набрать 123456789012345 (15 цифр) 2. Нажать 6 | H8: 1. Экран: 123 456 789 012 345 2. Экран не изменился: 123 456 789 012 345 | I8: Набирается число из 15 цифр; следующие цифры не принимаются, пока число не завершено. | J8: Не выполнялся
A9: TC-INP-07 | B9: Не более 15 цифр в дробном числе | C9: Ввод чисел | D9: Низкий | E9: «Ввод» | F9: ОП-1. | G9: 1. Набрать 1,23456789012345 (15 цифр) 2. Нажать 6 | H9: 1. Экран: 1,23456789012345 2. Экран не изменился: 1,23456789012345 | I9: Набирается число из 15 цифр; запятая в лимит не входит. | J9: Не выполнялся
A10: TC-INP-08 | B10: Разбиение на разряды при вводе | C10: Ввод чисел | D10: Средний | E10: «Ввод» | F10: ОП-1. | G10: 1. Набрать 1234 2. Нажать 5, 6, 7 3. Набрать ,5 | H10: 1. Экран: 1 234 2. Экран: 1 234 567 3. Экран: 1 234 567,5; дробная часть на разряды не разбивается | I10: Набирается число 1 234 567,5. | J10: Не выполнялся
A11: TC-INP-09 | B11: Смена знака набираемого числа | C11: Ввод чисел | D11: Средний | E11: «Операции» (+/−), «Ввод» | F11: ОП-1. | G11: 1. Набрать 3,5 2. Нажать +/− 3. Нажать +/− | H11: 1. Экран: 3,5 2. Экран: -3,5; выражение пустое 3. Экран: 3,5 | I11: Набирается число 3,5; ввод можно продолжить. | J11: Не выполнялся
A12: TC-INP-10 | B12: Стирание последнего символа | C12: Ввод чисел | D12: Средний | E12: «Операции» (⌫) | F12: ОП-1. | G12: 1. Набрать 123 2. Нажать ⌫ 3. Нажать ⌫ два раза 4. Набрать 5, 5. Нажать ⌫ 6. Нажать 7 | H12: 1. Экран: 123 2. Экран: 12 3. Экран: 0 4. Экран: 5, 5. Экран: 5 6. Экран: 57 — разделитель действительно удалён | I12: Набирается число 57. | J12: Не выполнялся
A13: TC-INP-11 | B13: ⌫ не изменяет результат вычисления | C13: Ввод чисел | D13: Низкий | E13: «Операции» (⌫); эталон — калькулятор Windows | F13: ОП-1. | G13: 1. Набрать 2, нажать +, набрать 3, нажать = 2. Нажать ⌫ | H13: 1. Экран: 5; выражение: 2 + 3 = 2. Экран не изменился: 5; выражение очищено | I13: На экране результат 5; в журнале запись 2 + 3 = → 5. | J13: Не выполнялся
... A70: TC-KBD-05 | B70: Клавиши очистки | C70: Клавиатура | D70: Средний | E70: «Клавиатура» (Backspace, Delete, Esc) | F70: ОП-1. | G70: 1. Набрать 123, нажать Backspace 2. Нажать +, набрать 34, нажать Delete 3. Нажать Esc | H70: 1. Экран: 12 2. Экран: 0; выражение: 12 + 3. Экран: 0; выражение пустое | I70: Незавершённой операции нет; журнал пуст. | J70: Не выполнялся

Sheet Сводка
A1: Прогон тестов: калькулятор, JS-версия
A3: Параметры прогона
A4: Версия сборки | E4: из подвала страницы калькулятора, например 1.0.0
A5: Стенд | E5: https://calc.simdyanov.ru, http://localhost:5173 или http://localhost:8080
A6: Браузер и ОС | E6: например, Chrome 140, macOS 26
A7: Тестировщик
A8: Дата начала | E8: ДД.ММ.ГГГГ
A9: Дата окончания | E9: ДД.ММ.ГГГГ
A11: Итоги
A12: Всего кейсов | B12: =COUNTA(Прогон!$A$2:$A$500) -> 69
A13: Пройден | B13: =COUNTIF(Прогон!$J$2:$J$500,"Пройден") -> 0
A14: Не пройден | B14: =COUNTIF(Прогон!$J$2:$J$500,"Не пройден") -> 0
A15: Заблокирован | B15: =COUNTIF(Прогон!$J$2:$J$500,"Заблокирован") -> 0
A16: Пропущен | B16: =COUNTIF(Прогон!$J$2:$J$500,"Пропущен") -> 0
A17: Не выполнялся | B17: =B12-SUM(B13:B16) -> 69 | C17: включая кейсы с пустым статусом
A18: Выполнено | B18: =IF(B12=0,0,(B13+B14)/B12) -> 0 | C18: доля кейсов со статусом «Пройден» или «Не пройден»
A19: Пройдено из выполненных | B19: =IF(B13+B14=0,"—",B13/(B13+B14)) -> — | C19: «—», пока ни один кейс не выполнен
A21: По разделам
A22: Раздел | B22: Всего | C22: Пройден | D22: Не пройден | E22: Заблокирован | F22: Пропущен | G22: Не выполнялся
A23: Интерфейс | B23: =COUNTIF(Прогон!$C$2:$C$500,$A23) -> 1 | C23: =COUNTIFS(Прогон!$C$2:$C$500,$A23,Прогон!$J$2:$J$500,C$22) -> 0 | D23: =COUNTIFS(Прогон!$C$2:$C$500,$A23,Прогон!$J$2:$J$500,D$22) -> 0 | E23: =COUNTIFS(Прогон!$C$2:$C$500,$A23,Прогон!$J$2:$J$500,E$22) -> 0 | F23: =COUNTIFS(Прогон!$C$2:$C$500,$A23,Прогон!$J$2:$J$500,F$22) -> 0 | G23: =B23-SUM(C23:F23) -> 1
A24: Ввод чисел | B24: =COUNTIF(Прогон!$C$2:$C$500,$A24) -> 14 | C24: =COUNTIFS(Прогон!$C$2:$C$500,$A24,Прогон!$J$2:$J$500,C$22) -> 0 | D24: =COUNTIFS(Прогон!$C$2:$C$500,$A24,Прогон!$J$2:$J$500,D$22) -> 0 | E24: =COUNTIFS(Прогон!$C$2:$C$500,$A24,Прогон!$J$2:$J$500,E$22) -> 0 | F24: =COUNTIFS(Прогон!$C$2:$C$500,$A24,Прогон!$J$2:$J$500,F$22) -> 0 | G24: =B24-SUM(C24:F24) -> 14
A25: Функции | B25: =COUNTIF(Прогон!$C$2:$C$500,$A25) -> 14 | C25: =COUNTIFS(Прогон!$C$2:$C$500,$A25,Прогон!$J$2:$J$500,C$22) -> 0 | D25: =COUNTIFS(Прогон!$C$2:$C$500,$A25,Прогон!$J$2:$J$500,D$22) -> 0 | E25: =COUNTIFS(Прогон!$C$2:$C$500,$A25,Прогон!$J$2:$J$500,E$22) -> 0 | F25: =COUNTIFS(Прогон!$C$2:$C$500,$A25,Прогон!$J$2:$J$500,F$22) -> 0 | G25: =B25-SUM(C25:F25) -> 14
A26: Память | B26: =COUNTIF(Прогон!$C$2:$C$500,$A26) -> 10 | C26: =COUNTIFS(Прогон!$C$2:$C$500,$A26,Прогон!$J$2:$J$500,C$22) -> 0 | D26: =COUNTIFS(Прогон!$C$2:$C$500,$A26,Прогон!$J$2:$J$500,D$22) -> 0 | E26: =COUNTIFS(Прогон!$C$2:$C$500,$A26,Прогон!$J$2:$J$500,E$22) -> 0 | F26: =COUNTIFS(Прогон!$C$2:$C$500,$A26,Прогон!$J$2:$J$500,F$22) -> 0 | G26: =B26-SUM(C26:F26) -> 10
A27: Ошибки | B27: =COUNTIF(Прогон!$C$2:$C$500,$A27) -> 9 | C27: =COUNTIFS(Прогон!$C$2:$C$500,$A27,Прогон!$J$2:$J$500,C$22) -> 0 | D27: =COUNTIFS(Прогон!$C$2:$C$500,$A27,Прогон!$J$2:$J$500,D$22) -> 0 | E27: =COUNTIFS(Прогон!$C$2:$C$500,$A27,Прогон!$J$2:$J$500,E$22) -> 0 | F27: =COUNTIFS(Прогон!$C$2:$C$500,$A27,Прогон!$J$2:$J$500,F$22) -> 0 | G27: =B27-SUM(C27:F27) -> 9
A28: Формат вывода | B28: =COUNTIF(Прогон!$C$2:$C$500,$A28) -> 5 | C28: =COUNTIFS(Прогон!$C$2:$C$500,$A28,Прогон!$J$2:$J$500,C$22) -> 0 | D28: =COUNTIFS(Прогон!$C$2:$C$500,$A28,Прогон!$J$2:$J$500,D$22) -> 0 | E28: =COUNTIFS(Прогон!$C$2:$C$500,$A28,Прогон!$J$2:$J$500,E$22) -> 0 | F28: =COUNTIFS(Прогон!$C$2:$C$500,$A28,Прогон!$J$2:$J$500,F$22) -> 0 | G28: =B28-SUM(C28:F28) -> 5
A29: Журнал | B29: =COUNTIF(Прогон!$C$2:$C$500,$A29) -> 11 | C29: =COUNTIFS(Прогон!$C$2:$C$500,$A29,Прогон!$J$2:$J$500,C$22) -> 0 | D29: =COUNTIFS(Прогон!$C$2:$C$500,$A29,Прогон!$J$2:$J$500,D$22) -> 0 | E29: =COUNTIFS(Прогон!$C$2:$C$500,$A29,Прогон!$J$2:$J$500,E$22) -> 0 | F29: =COUNTIFS(Прогон!$C$2:$C$500,$A29,Прогон!$J$2:$J$500,F$22) -> 0 | G29: =B29-SUM(C29:F29) -> 11
A30: Клавиатура | B30: =COUNTIF(Прогон!$C$2:$C$500,$A30) -> 5 | C30: =COUNTIFS(Прогон!$C$2:$C$500,$A30,Прогон!$J$2:$J$500,C$22) -> 0 | D30: =COUNTIFS(Прогон!$C$2:$C$500,$A30,Прогон!$J$2:$J$500,D$22) -> 0 | E30: =COUNTIFS(Прогон!$C$2:$C$500,$A30,Прогон!$J$2:$J$500,E$22) -> 0 | F30: =COUNTIFS(Прогон!$C$2:$C$500,$A30,Прогон!$J$2:$J$500,F$22) -> 0 | G30: =B30-SUM(C30:F30) -> 5
A31: Итого | B31: =SUM(B23:B30) -> 69 | C31: =SUM(C23:C30) -> 0 | D31: =SUM(D23:D30) -> 0 | E31: =SUM(E23:E30) -> 0 | F31: =SUM(F23:F30) -> 0 | G31: =SUM(G23:G30) -> 69
A33: По приоритетам
A34: Приоритет | B34: Всего | C34: Пройден | D34: Не пройден | E34: Заблокирован | F34: Пропущен | G34: Не выполнялся
A35: Высокий | B35: =COUNTIF(Прогон!$D$2:$D$500,$A35) -> 26 | C35: =COUNTIFS(Прогон!$D$2:$D$500,$A35,Прогон!$J$2:$J$500,C$34) -> 0 | D35: =COUNTIFS(Прогон!$D$2:$D$500,$A35,Прогон!$J$2:$J$500,D$34) -> 0 | E35: =COUNTIFS(Прогон!$D$2:$D$500,$A35,Прогон!$J$2:$J$500,E$34) -> 0 | F35: =COUNTIFS(Прогон!$D$2:$D$500,$A35,Прогон!$J$2:$J$500,F$34) -> 0 | G35: =B35-SUM(C35:F35) -> 26
A36: Средний | B36: =COUNTIF(Прогон!$D$2:$D$500,$A36) -> 36 | C36: =COUNTIFS(Прогон!$D$2:$D$500,$A36,Прогон!$J$2:$J$500,C$34) -> 0 | D36: =COUNTIFS(Прогон!$D$2:$D$500,$A36,Прогон!$J$2:$J$500,D$34) -> 0 | E36: =COUNTIFS(Прогон!$D$2:$D$500,$A36,Прогон!$J$2:$J$500,E$34) -> 0 | F36: =COUNTIFS(Прогон!$D$2:$D$500,$A36,Прогон!$J$2:$J$500,F$34) -> 0 | G36: =B36-SUM(C36:F36) -> 36
A37: Низкий | B37: =COUNTIF(Прогон!$D$2:$D$500,$A37) -> 7 | C37: =COUNTIFS(Прогон!$D$2:$D$500,$A37,Прогон!$J$2:$J$500,C$34) -> 0 | D37: =COUNTIFS(Прогон!$D$2:$D$500,$A37,Прогон!$J$2:$J$500,D$34) -> 0 | E37: =COUNTIFS(Прогон!$D$2:$D$500,$A37,Прогон!$J$2:$J$500,E$34) -> 0 | F37: =COUNTIFS(Прогон!$D$2:$D$500,$A37,Прогон!$J$2:$J$500,F$34) -> 0 | G37: =B37-SUM(C37:F37) -> 7
A38: Итого | B38: =SUM(B35:B37) -> 69 | C38: =SUM(C35:C37) -> 0 | D38: =SUM(D35:D37) -> 0 | E38: =SUM(E35:E37) -> 0 | F38: =SUM(F35:F37) -> 0 | G38: =SUM(G35:G37) -> 69
